2022-02-14 01:05:42,013 Downloading artifact
2022-02-14 01:05:43,641 Dropping duplicates
2022-02-14 01:05:43,655 Feature engineering
Traceback (most recent call last):
  File "/Users/wasuratsoontronchai/opt/anaconda3/envs/mlflow-318b5229405b42f2d2684d461f99cd02f4e8b258/lib/python3.8/site-packages/pandas/core/indexes/base.py", line 3080, in get_loc
    return self._engine.get_loc(casted_key)
  File "pandas/_libs/index.pyx", line 70, in pandas._libs.index.IndexEngine.get_loc
  File "pandas/_libs/index.pyx", line 101, in pandas._libs.index.IndexEngine.get_loc
  File "pandas/_libs/hashtable_class_helper.pxi", line 4554, in pandas._libs.hashtable.PyObjectHashTable.get_item
  File "pandas/_libs/hashtable_class_helper.pxi", line 4562, in pandas._libs.hashtable.PyObjectHashTable.get_item
KeyError: 'title'

The above exception was the direct cause of the following exception:

Traceback (most recent call last):
  File "run.py", line 80, in <module>
    go(args)
  File "run.py", line 30, in go
    df['title'].fillna(value='', inplace=True)
  File "/Users/wasuratsoontronchai/opt/anaconda3/envs/mlflow-318b5229405b42f2d2684d461f99cd02f4e8b258/lib/python3.8/site-packages/pandas/core/frame.py", line 3024, in __getitem__
    indexer = self.columns.get_loc(key)
  File "/Users/wasuratsoontronchai/opt/anaconda3/envs/mlflow-318b5229405b42f2d2684d461f99cd02f4e8b258/lib/python3.8/site-packages/pandas/core/indexes/base.py", line 3082, in get_loc
    raise KeyError(key) from err
KeyError: 'title'
